Traceback (most recent call last):
  File "/Users/janjagusch/mambaforge/envs/quetz-client/lib/python3.11/site-packages/pudb/__init__.py", line 158, in runscript
    dbg._runscript(mainpyfile)
  File "/Users/janjagusch/mambaforge/envs/quetz-client/lib/python3.11/site-packages/pudb/debugger.py", line 526, in _runscript
    self.run(statement)
  File "/Users/janjagusch/mambaforge/envs/quetz-client/lib/python3.11/bdb.py", line 597, in run
    exec(cmd, globals, locals)
  File "<string>", line 1, in <module>
  File "test.py", line 3, in <module>
    run_action("jupyter-releaser draft-changelog")
  File "/Users/janjagusch/mambaforge/envs/quetz-client/lib/python3.11/site-packages/jupyter_releaser/actions/common.py", line 25, in run_action
    _run(target, *args, **kwargs)
  File "/Users/janjagusch/mambaforge/envs/quetz-client/lib/python3.11/site-packages/jupyter_releaser/util.py", line 91, in run
    raise e
  File "/Users/janjagusch/mambaforge/envs/quetz-client/lib/python3.11/site-packages/jupyter_releaser/util.py", line 83, in run
    process = tee(cmd, **kwargs)
              ^^^^^^^^^^^^^^^^^^
  File "/Users/janjagusch/mambaforge/envs/quetz-client/lib/python3.11/site-packages/jupyter_releaser/tee.py", line 159, in run
    raise subprocess.CalledProcessError(
subprocess.CalledProcessError: Command 'jupyter-releaser draft-changelog' returned non-zero exit status 1.
